{
 "cells": [
  {
   "cell_type": "markdown",
   "metadata": {},
   "source": [
    "# Load Data\n",
    "> Connect and Read From the Database. Needs `USER`, `PASS`, `IP`, `PORT`, `DB` environment variables"
   ]
  },
  {
   "cell_type": "code",
   "execution_count": null,
   "metadata": {},
   "outputs": [],
   "source": [
    "#| default_exp etl.national.load"
   ]
  },
  {
   "cell_type": "code",
   "execution_count": null,
   "metadata": {},
   "outputs": [],
   "source": [
    "#| export\n",
    "from sqlalchemy import create_engine\n",
    "from niloIQ2.etl import tables\n",
    "\n",
    "import pandas as pd\n",
    "import os\n",
    "import pathlib\n",
    "from dotenv import load_dotenv"
   ]
  },
  {
   "cell_type": "code",
   "execution_count": null,
   "metadata": {},
   "outputs": [
    {
     "data": {
      "text/plain": [
       "[<nilo_iq.tables.Table at 0x7fd69cc0b760>,\n",
       " <nilo_iq.tables.Table at 0x7fd69d8e5ca0>]"
      ]
     },
     "execution_count": null,
     "metadata": {},
     "output_type": "execute_result"
    }
   ],
   "source": [
    "tables.national_list"
   ]
  },
  {
   "cell_type": "code",
   "execution_count": null,
   "metadata": {},
   "outputs": [
    {
     "ename": "OperationalError",
     "evalue": "(pymysql.err.OperationalError) (2003, \"Can't connect to MySQL server on 'None' ([Errno -2] Name or service not known)\")\n(Background on this error at: http://sqlalche.me/e/13/e3q8)",
     "output_type": "error",
     "traceback": [
      "\u001b[0;31m---------------------------------------------------------------------------\u001b[0m",
      "\u001b[0;31mgaierror\u001b[0m                                  Traceback (most recent call last)",
      "File \u001b[0;32m/opt/conda/lib/python3.8/site-packages/pymysql/connections.py:613\u001b[0m, in \u001b[0;36mConnection.connect\u001b[0;34m(self, sock)\u001b[0m\n\u001b[1;32m    612\u001b[0m \u001b[39mtry\u001b[39;00m:\n\u001b[0;32m--> 613\u001b[0m     sock \u001b[39m=\u001b[39m socket\u001b[39m.\u001b[39;49mcreate_connection(\n\u001b[1;32m    614\u001b[0m         (\u001b[39mself\u001b[39;49m\u001b[39m.\u001b[39;49mhost, \u001b[39mself\u001b[39;49m\u001b[39m.\u001b[39;49mport), \u001b[39mself\u001b[39;49m\u001b[39m.\u001b[39;49mconnect_timeout, \u001b[39m*\u001b[39;49m\u001b[39m*\u001b[39;49mkwargs\n\u001b[1;32m    615\u001b[0m     )\n\u001b[1;32m    616\u001b[0m     \u001b[39mbreak\u001b[39;00m\n",
      "File \u001b[0;32m/opt/conda/lib/python3.8/socket.py:787\u001b[0m, in \u001b[0;36mcreate_connection\u001b[0;34m(address, timeout, source_address)\u001b[0m\n\u001b[1;32m    786\u001b[0m err \u001b[39m=\u001b[39m \u001b[39mNone\u001b[39;00m\n\u001b[0;32m--> 787\u001b[0m \u001b[39mfor\u001b[39;00m res \u001b[39min\u001b[39;00m getaddrinfo(host, port, \u001b[39m0\u001b[39;49m, SOCK_STREAM):\n\u001b[1;32m    788\u001b[0m     af, socktype, proto, canonname, sa \u001b[39m=\u001b[39m res\n",
      "File \u001b[0;32m/opt/conda/lib/python3.8/socket.py:918\u001b[0m, in \u001b[0;36mgetaddrinfo\u001b[0;34m(host, port, family, type, proto, flags)\u001b[0m\n\u001b[1;32m    917\u001b[0m addrlist \u001b[39m=\u001b[39m []\n\u001b[0;32m--> 918\u001b[0m \u001b[39mfor\u001b[39;00m res \u001b[39min\u001b[39;00m _socket\u001b[39m.\u001b[39;49mgetaddrinfo(host, port, family, \u001b[39mtype\u001b[39;49m, proto, flags):\n\u001b[1;32m    919\u001b[0m     af, socktype, proto, canonname, sa \u001b[39m=\u001b[39m res\n",
      "\u001b[0;31mgaierror\u001b[0m: [Errno -2] Name or service not known",
      "\nDuring handling of the above exception, another exception occurred:\n",
      "\u001b[0;31mOperationalError\u001b[0m                          Traceback (most recent call last)",
      "File \u001b[0;32m/opt/conda/lib/python3.8/site-packages/sqlalchemy/engine/base.py:2336\u001b[0m, in \u001b[0;36mEngine._wrap_pool_connect\u001b[0;34m(self, fn, connection)\u001b[0m\n\u001b[1;32m   2335\u001b[0m \u001b[39mtry\u001b[39;00m:\n\u001b[0;32m-> 2336\u001b[0m     \u001b[39mreturn\u001b[39;00m fn()\n\u001b[1;32m   2337\u001b[0m \u001b[39mexcept\u001b[39;00m dialect\u001b[39m.\u001b[39mdbapi\u001b[39m.\u001b[39mError \u001b[39mas\u001b[39;00m e:\n",
      "File \u001b[0;32m/opt/conda/lib/python3.8/site-packages/sqlalchemy/pool/base.py:304\u001b[0m, in \u001b[0;36mPool.unique_connection\u001b[0;34m(self)\u001b[0m\n\u001b[1;32m    293\u001b[0m \u001b[39m\"\"\"Produce a DBAPI connection that is not referenced by any\u001b[39;00m\n\u001b[1;32m    294\u001b[0m \u001b[39mthread-local context.\u001b[39;00m\n\u001b[1;32m    295\u001b[0m \n\u001b[0;32m   (...)\u001b[0m\n\u001b[1;32m    302\u001b[0m \n\u001b[1;32m    303\u001b[0m \u001b[39m\"\"\"\u001b[39;00m\n\u001b[0;32m--> 304\u001b[0m \u001b[39mreturn\u001b[39;00m _ConnectionFairy\u001b[39m.\u001b[39;49m_checkout(\u001b[39mself\u001b[39;49m)\n",
      "File \u001b[0;32m/opt/conda/lib/python3.8/site-packages/sqlalchemy/pool/base.py:778\u001b[0m, in \u001b[0;36m_ConnectionFairy._checkout\u001b[0;34m(cls, pool, threadconns, fairy)\u001b[0m\n\u001b[1;32m    777\u001b[0m \u001b[39mif\u001b[39;00m \u001b[39mnot\u001b[39;00m fairy:\n\u001b[0;32m--> 778\u001b[0m     fairy \u001b[39m=\u001b[39m _ConnectionRecord\u001b[39m.\u001b[39;49mcheckout(pool)\n\u001b[1;32m    780\u001b[0m     fairy\u001b[39m.\u001b[39m_pool \u001b[39m=\u001b[39m pool\n",
      "File \u001b[0;32m/opt/conda/lib/python3.8/site-packages/sqlalchemy/pool/base.py:495\u001b[0m, in \u001b[0;36m_ConnectionRecord.checkout\u001b[0;34m(cls, pool)\u001b[0m\n\u001b[1;32m    493\u001b[0m \u001b[39m@classmethod\u001b[39m\n\u001b[1;32m    494\u001b[0m \u001b[39mdef\u001b[39;00m \u001b[39mcheckout\u001b[39m(\u001b[39mcls\u001b[39m, pool):\n\u001b[0;32m--> 495\u001b[0m     rec \u001b[39m=\u001b[39m pool\u001b[39m.\u001b[39;49m_do_get()\n\u001b[1;32m    496\u001b[0m     \u001b[39mtry\u001b[39;00m:\n",
      "File \u001b[0;32m/opt/conda/lib/python3.8/site-packages/sqlalchemy/pool/impl.py:140\u001b[0m, in \u001b[0;36mQueuePool._do_get\u001b[0;34m(self)\u001b[0m\n\u001b[1;32m    139\u001b[0m         \u001b[39mwith\u001b[39;00m util\u001b[39m.\u001b[39msafe_reraise():\n\u001b[0;32m--> 140\u001b[0m             \u001b[39mself\u001b[39m\u001b[39m.\u001b[39m_dec_overflow()\n\u001b[1;32m    141\u001b[0m \u001b[39melse\u001b[39;00m:\n",
      "File \u001b[0;32m/opt/conda/lib/python3.8/site-packages/sqlalchemy/util/langhelpers.py:68\u001b[0m, in \u001b[0;36msafe_reraise.__exit__\u001b[0;34m(self, type_, value, traceback)\u001b[0m\n\u001b[1;32m     67\u001b[0m     \u001b[39mif\u001b[39;00m \u001b[39mnot\u001b[39;00m \u001b[39mself\u001b[39m\u001b[39m.\u001b[39mwarn_only:\n\u001b[0;32m---> 68\u001b[0m         compat\u001b[39m.\u001b[39;49mraise_(\n\u001b[1;32m     69\u001b[0m             exc_value,\n\u001b[1;32m     70\u001b[0m             with_traceback\u001b[39m=\u001b[39;49mexc_tb,\n\u001b[1;32m     71\u001b[0m         )\n\u001b[1;32m     72\u001b[0m \u001b[39melse\u001b[39;00m:\n",
      "File \u001b[0;32m/opt/conda/lib/python3.8/site-packages/sqlalchemy/util/compat.py:182\u001b[0m, in \u001b[0;36mraise_\u001b[0;34m(***failed resolving arguments***)\u001b[0m\n\u001b[1;32m    181\u001b[0m \u001b[39mtry\u001b[39;00m:\n\u001b[0;32m--> 182\u001b[0m     \u001b[39mraise\u001b[39;00m exception\n\u001b[1;32m    183\u001b[0m \u001b[39mfinally\u001b[39;00m:\n\u001b[1;32m    184\u001b[0m     \u001b[39m# credit to\u001b[39;00m\n\u001b[1;32m    185\u001b[0m     \u001b[39m# https://cosmicpercolator.com/2016/01/13/exception-leaks-in-python-2-and-3/\u001b[39;00m\n\u001b[1;32m    186\u001b[0m     \u001b[39m# as the __traceback__ object creates a cycle\u001b[39;00m\n",
      "File \u001b[0;32m/opt/conda/lib/python3.8/site-packages/sqlalchemy/pool/impl.py:137\u001b[0m, in \u001b[0;36mQueuePool._do_get\u001b[0;34m(self)\u001b[0m\n\u001b[1;32m    136\u001b[0m \u001b[39mtry\u001b[39;00m:\n\u001b[0;32m--> 137\u001b[0m     \u001b[39mreturn\u001b[39;00m \u001b[39mself\u001b[39;49m\u001b[39m.\u001b[39;49m_create_connection()\n\u001b[1;32m    138\u001b[0m \u001b[39mexcept\u001b[39;00m:\n",
      "File \u001b[0;32m/opt/conda/lib/python3.8/site-packages/sqlalchemy/pool/base.py:309\u001b[0m, in \u001b[0;36mPool._create_connection\u001b[0;34m(self)\u001b[0m\n\u001b[1;32m    307\u001b[0m \u001b[39m\"\"\"Called by subclasses to create a new ConnectionRecord.\"\"\"\u001b[39;00m\n\u001b[0;32m--> 309\u001b[0m \u001b[39mreturn\u001b[39;00m _ConnectionRecord(\u001b[39mself\u001b[39;49m)\n",
      "File \u001b[0;32m/opt/conda/lib/python3.8/site-packages/sqlalchemy/pool/base.py:440\u001b[0m, in \u001b[0;36m_ConnectionRecord.__init__\u001b[0;34m(self, pool, connect)\u001b[0m\n\u001b[1;32m    439\u001b[0m \u001b[39mif\u001b[39;00m connect:\n\u001b[0;32m--> 440\u001b[0m     \u001b[39mself\u001b[39;49m\u001b[39m.\u001b[39;49m__connect(first_connect_check\u001b[39m=\u001b[39;49m\u001b[39mTrue\u001b[39;49;00m)\n\u001b[1;32m    441\u001b[0m \u001b[39mself\u001b[39m\u001b[39m.\u001b[39mfinalize_callback \u001b[39m=\u001b[39m deque()\n",
      "File \u001b[0;32m/opt/conda/lib/python3.8/site-packages/sqlalchemy/pool/base.py:661\u001b[0m, in \u001b[0;36m_ConnectionRecord.__connect\u001b[0;34m(self, first_connect_check)\u001b[0m\n\u001b[1;32m    660\u001b[0m     \u001b[39mwith\u001b[39;00m util\u001b[39m.\u001b[39msafe_reraise():\n\u001b[0;32m--> 661\u001b[0m         pool\u001b[39m.\u001b[39mlogger\u001b[39m.\u001b[39mdebug(\u001b[39m\"\u001b[39m\u001b[39mError on connect(): \u001b[39m\u001b[39m%s\u001b[39;00m\u001b[39m\"\u001b[39m, e)\n\u001b[1;32m    662\u001b[0m \u001b[39melse\u001b[39;00m:\n",
      "File \u001b[0;32m/opt/conda/lib/python3.8/site-packages/sqlalchemy/util/langhelpers.py:68\u001b[0m, in \u001b[0;36msafe_reraise.__exit__\u001b[0;34m(self, type_, value, traceback)\u001b[0m\n\u001b[1;32m     67\u001b[0m     \u001b[39mif\u001b[39;00m \u001b[39mnot\u001b[39;00m \u001b[39mself\u001b[39m\u001b[39m.\u001b[39mwarn_only:\n\u001b[0;32m---> 68\u001b[0m         compat\u001b[39m.\u001b[39;49mraise_(\n\u001b[1;32m     69\u001b[0m             exc_value,\n\u001b[1;32m     70\u001b[0m             with_traceback\u001b[39m=\u001b[39;49mexc_tb,\n\u001b[1;32m     71\u001b[0m         )\n\u001b[1;32m     72\u001b[0m \u001b[39melse\u001b[39;00m:\n",
      "File \u001b[0;32m/opt/conda/lib/python3.8/site-packages/sqlalchemy/util/compat.py:182\u001b[0m, in \u001b[0;36mraise_\u001b[0;34m(***failed resolving arguments***)\u001b[0m\n\u001b[1;32m    181\u001b[0m \u001b[39mtry\u001b[39;00m:\n\u001b[0;32m--> 182\u001b[0m     \u001b[39mraise\u001b[39;00m exception\n\u001b[1;32m    183\u001b[0m \u001b[39mfinally\u001b[39;00m:\n\u001b[1;32m    184\u001b[0m     \u001b[39m# credit to\u001b[39;00m\n\u001b[1;32m    185\u001b[0m     \u001b[39m# https://cosmicpercolator.com/2016/01/13/exception-leaks-in-python-2-and-3/\u001b[39;00m\n\u001b[1;32m    186\u001b[0m     \u001b[39m# as the __traceback__ object creates a cycle\u001b[39;00m\n",
      "File \u001b[0;32m/opt/conda/lib/python3.8/site-packages/sqlalchemy/pool/base.py:656\u001b[0m, in \u001b[0;36m_ConnectionRecord.__connect\u001b[0;34m(self, first_connect_check)\u001b[0m\n\u001b[1;32m    655\u001b[0m \u001b[39mself\u001b[39m\u001b[39m.\u001b[39mstarttime \u001b[39m=\u001b[39m time\u001b[39m.\u001b[39mtime()\n\u001b[0;32m--> 656\u001b[0m connection \u001b[39m=\u001b[39m pool\u001b[39m.\u001b[39;49m_invoke_creator(\u001b[39mself\u001b[39;49m)\n\u001b[1;32m    657\u001b[0m pool\u001b[39m.\u001b[39mlogger\u001b[39m.\u001b[39mdebug(\u001b[39m\"\u001b[39m\u001b[39mCreated new connection \u001b[39m\u001b[39m%r\u001b[39;00m\u001b[39m\"\u001b[39m, connection)\n",
      "File \u001b[0;32m/opt/conda/lib/python3.8/site-packages/sqlalchemy/engine/strategies.py:114\u001b[0m, in \u001b[0;36mDefaultEngineStrategy.create.<locals>.connect\u001b[0;34m(connection_record)\u001b[0m\n\u001b[1;32m    113\u001b[0m             \u001b[39mreturn\u001b[39;00m connection\n\u001b[0;32m--> 114\u001b[0m \u001b[39mreturn\u001b[39;00m dialect\u001b[39m.\u001b[39;49mconnect(\u001b[39m*\u001b[39;49mcargs, \u001b[39m*\u001b[39;49m\u001b[39m*\u001b[39;49mcparams)\n",
      "File \u001b[0;32m/opt/conda/lib/python3.8/site-packages/sqlalchemy/engine/default.py:508\u001b[0m, in \u001b[0;36mDefaultDialect.connect\u001b[0;34m(self, *cargs, **cparams)\u001b[0m\n\u001b[1;32m    506\u001b[0m \u001b[39mdef\u001b[39;00m \u001b[39mconnect\u001b[39m(\u001b[39mself\u001b[39m, \u001b[39m*\u001b[39mcargs, \u001b[39m*\u001b[39m\u001b[39m*\u001b[39mcparams):\n\u001b[1;32m    507\u001b[0m     \u001b[39m# inherits the docstring from interfaces.Dialect.connect\u001b[39;00m\n\u001b[0;32m--> 508\u001b[0m     \u001b[39mreturn\u001b[39;00m \u001b[39mself\u001b[39;49m\u001b[39m.\u001b[39;49mdbapi\u001b[39m.\u001b[39;49mconnect(\u001b[39m*\u001b[39;49mcargs, \u001b[39m*\u001b[39;49m\u001b[39m*\u001b[39;49mcparams)\n",
      "File \u001b[0;32m/opt/conda/lib/python3.8/site-packages/pymysql/connections.py:353\u001b[0m, in \u001b[0;36mConnection.__init__\u001b[0;34m(self, user, password, host, database, unix_socket, port, charset, sql_mode, read_default_file, conv, use_unicode, client_flag, cursorclass, init_command, connect_timeout, read_default_group, autocommit, local_infile, max_allowed_packet, defer_connect, auth_plugin_map, read_timeout, write_timeout, bind_address, binary_prefix, program_name, server_public_key, ssl, ssl_ca, ssl_cert, ssl_disabled, ssl_key, ssl_verify_cert, ssl_verify_identity, compress, named_pipe, passwd, db)\u001b[0m\n\u001b[1;32m    352\u001b[0m \u001b[39melse\u001b[39;00m:\n\u001b[0;32m--> 353\u001b[0m     \u001b[39mself\u001b[39;49m\u001b[39m.\u001b[39;49mconnect()\n",
      "File \u001b[0;32m/opt/conda/lib/python3.8/site-packages/pymysql/connections.py:664\u001b[0m, in \u001b[0;36mConnection.connect\u001b[0;34m(self, sock)\u001b[0m\n\u001b[1;32m    663\u001b[0m         \u001b[39mprint\u001b[39m(exc\u001b[39m.\u001b[39mtraceback)\n\u001b[0;32m--> 664\u001b[0m     \u001b[39mraise\u001b[39;00m exc\n\u001b[1;32m    666\u001b[0m \u001b[39m# If e is neither DatabaseError or IOError, It's a bug.\u001b[39;00m\n\u001b[1;32m    667\u001b[0m \u001b[39m# But raising AssertionError hides original error.\u001b[39;00m\n\u001b[1;32m    668\u001b[0m \u001b[39m# So just reraise it.\u001b[39;00m\n",
      "\u001b[0;31mOperationalError\u001b[0m: (2003, \"Can't connect to MySQL server on 'None' ([Errno -2] Name or service not known)\")",
      "\nThe above exception was the direct cause of the following exception:\n",
      "\u001b[0;31mOperationalError\u001b[0m                          Traceback (most recent call last)",
      "\u001b[1;32m/workspaces/nilo_iq/nbs/NationalPrices/01_LoadData.ipynb Cell 5\u001b[0m in \u001b[0;36m<cell line: 14>\u001b[0;34m()\u001b[0m\n\u001b[1;32m      <a href='vscode-notebook-cell://dev-container%2B2f686f6d652f656e72697175652f6e696c6f5f69712f6e696c6f5f6971/workspaces/nilo_iq/nbs/NationalPrices/01_LoadData.ipynb#W4sdnNjb2RlLXJlbW90ZQ%3D%3D?line=8'>9</a>\u001b[0m DB \u001b[39m=\u001b[39m os\u001b[39m.\u001b[39mgetenv(\u001b[39m'\u001b[39m\u001b[39mDB\u001b[39m\u001b[39m'\u001b[39m)\n\u001b[1;32m     <a href='vscode-notebook-cell://dev-container%2B2f686f6d652f656e72697175652f6e696c6f5f69712f6e696c6f5f6971/workspaces/nilo_iq/nbs/NationalPrices/01_LoadData.ipynb#W4sdnNjb2RlLXJlbW90ZQ%3D%3D?line=10'>11</a>\u001b[0m sqlEngine \u001b[39m=\u001b[39m create_engine(\n\u001b[1;32m     <a href='vscode-notebook-cell://dev-container%2B2f686f6d652f656e72697175652f6e696c6f5f69712f6e696c6f5f6971/workspaces/nilo_iq/nbs/NationalPrices/01_LoadData.ipynb#W4sdnNjb2RlLXJlbW90ZQ%3D%3D?line=11'>12</a>\u001b[0m     \u001b[39mf\u001b[39m\u001b[39m'\u001b[39m\u001b[39mmysql+pymysql://\u001b[39m\u001b[39m{\u001b[39;00mUSER\u001b[39m}\u001b[39;00m\u001b[39m:\u001b[39m\u001b[39m{\u001b[39;00mPASS\u001b[39m}\u001b[39;00m\u001b[39m@\u001b[39m\u001b[39m{\u001b[39;00mHOST\u001b[39m}\u001b[39;00m\u001b[39m/\u001b[39m\u001b[39m{\u001b[39;00mDB\u001b[39m}\u001b[39;00m\u001b[39m'\u001b[39m, pool_recycle\u001b[39m=\u001b[39m\u001b[39m3600\u001b[39m\n\u001b[1;32m     <a href='vscode-notebook-cell://dev-container%2B2f686f6d652f656e72697175652f6e696c6f5f69712f6e696c6f5f6971/workspaces/nilo_iq/nbs/NationalPrices/01_LoadData.ipynb#W4sdnNjb2RlLXJlbW90ZQ%3D%3D?line=12'>13</a>\u001b[0m )\n\u001b[0;32m---> <a href='vscode-notebook-cell://dev-container%2B2f686f6d652f656e72697175652f6e696c6f5f69712f6e696c6f5f6971/workspaces/nilo_iq/nbs/NationalPrices/01_LoadData.ipynb#W4sdnNjb2RlLXJlbW90ZQ%3D%3D?line=13'>14</a>\u001b[0m dbConnection \u001b[39m=\u001b[39m sqlEngine\u001b[39m.\u001b[39;49mconnect()\n\u001b[1;32m     <a href='vscode-notebook-cell://dev-container%2B2f686f6d652f656e72697175652f6e696c6f5f69712f6e696c6f5f6971/workspaces/nilo_iq/nbs/NationalPrices/01_LoadData.ipynb#W4sdnNjb2RlLXJlbW90ZQ%3D%3D?line=17'>18</a>\u001b[0m \u001b[39mfor\u001b[39;00m table \u001b[39min\u001b[39;00m tables\u001b[39m.\u001b[39mnational_list:\n\u001b[1;32m     <a href='vscode-notebook-cell://dev-container%2B2f686f6d652f656e72697175652f6e696c6f5f69712f6e696c6f5f6971/workspaces/nilo_iq/nbs/NationalPrices/01_LoadData.ipynb#W4sdnNjb2RlLXJlbW90ZQ%3D%3D?line=18'>19</a>\u001b[0m     df \u001b[39m=\u001b[39m pd\u001b[39m.\u001b[39mread_sql(\u001b[39mf\u001b[39m\u001b[39m\"\u001b[39m\u001b[39mselect * from \u001b[39m\u001b[39m{\u001b[39;00mtable\u001b[39m.\u001b[39mtable_name\u001b[39m}\u001b[39;00m\u001b[39m\"\u001b[39m, dbConnection)\n",
      "File \u001b[0;32m/opt/conda/lib/python3.8/site-packages/sqlalchemy/engine/base.py:2263\u001b[0m, in \u001b[0;36mEngine.connect\u001b[0;34m(self, **kwargs)\u001b[0m\n\u001b[1;32m   2248\u001b[0m \u001b[39mdef\u001b[39;00m \u001b[39mconnect\u001b[39m(\u001b[39mself\u001b[39m, \u001b[39m*\u001b[39m\u001b[39m*\u001b[39mkwargs):\n\u001b[1;32m   2249\u001b[0m     \u001b[39m\"\"\"Return a new :class:`_engine.Connection` object.\u001b[39;00m\n\u001b[1;32m   2250\u001b[0m \n\u001b[1;32m   2251\u001b[0m \u001b[39m    The :class:`_engine.Connection` object is a facade that uses a DBAPI\u001b[39;00m\n\u001b[0;32m   (...)\u001b[0m\n\u001b[1;32m   2260\u001b[0m \n\u001b[1;32m   2261\u001b[0m \u001b[39m    \"\"\"\u001b[39;00m\n\u001b[0;32m-> 2263\u001b[0m     \u001b[39mreturn\u001b[39;00m \u001b[39mself\u001b[39;49m\u001b[39m.\u001b[39;49m_connection_cls(\u001b[39mself\u001b[39;49m, \u001b[39m*\u001b[39;49m\u001b[39m*\u001b[39;49mkwargs)\n",
      "File \u001b[0;32m/opt/conda/lib/python3.8/site-packages/sqlalchemy/engine/base.py:104\u001b[0m, in \u001b[0;36mConnection.__init__\u001b[0;34m(self, engine, connection, close_with_result, _branch_from, _execution_options, _dispatch, _has_events)\u001b[0m\n\u001b[1;32m     99\u001b[0m     \u001b[39mself\u001b[39m\u001b[39m.\u001b[39mschema_for_object \u001b[39m=\u001b[39m _branch_from\u001b[39m.\u001b[39mschema_for_object\n\u001b[1;32m    100\u001b[0m \u001b[39melse\u001b[39;00m:\n\u001b[1;32m    101\u001b[0m     \u001b[39mself\u001b[39m\u001b[39m.\u001b[39m__connection \u001b[39m=\u001b[39m (\n\u001b[1;32m    102\u001b[0m         connection\n\u001b[1;32m    103\u001b[0m         \u001b[39mif\u001b[39;00m connection \u001b[39mis\u001b[39;00m \u001b[39mnot\u001b[39;00m \u001b[39mNone\u001b[39;00m\n\u001b[0;32m--> 104\u001b[0m         \u001b[39melse\u001b[39;00m engine\u001b[39m.\u001b[39;49mraw_connection()\n\u001b[1;32m    105\u001b[0m     )\n\u001b[1;32m    106\u001b[0m     \u001b[39mself\u001b[39m\u001b[39m.\u001b[39m__transaction \u001b[39m=\u001b[39m \u001b[39mNone\u001b[39;00m\n\u001b[1;32m    107\u001b[0m     \u001b[39mself\u001b[39m\u001b[39m.\u001b[39m__savepoint_seq \u001b[39m=\u001b[39m \u001b[39m0\u001b[39m\n",
      "File \u001b[0;32m/opt/conda/lib/python3.8/site-packages/sqlalchemy/engine/base.py:2369\u001b[0m, in \u001b[0;36mEngine.raw_connection\u001b[0;34m(self, _connection)\u001b[0m\n\u001b[1;32m   2347\u001b[0m \u001b[39mdef\u001b[39;00m \u001b[39mraw_connection\u001b[39m(\u001b[39mself\u001b[39m, _connection\u001b[39m=\u001b[39m\u001b[39mNone\u001b[39;00m):\n\u001b[1;32m   2348\u001b[0m     \u001b[39m\"\"\"Return a \"raw\" DBAPI connection from the connection pool.\u001b[39;00m\n\u001b[1;32m   2349\u001b[0m \n\u001b[1;32m   2350\u001b[0m \u001b[39m    The returned object is a proxied version of the DBAPI\u001b[39;00m\n\u001b[0;32m   (...)\u001b[0m\n\u001b[1;32m   2367\u001b[0m \n\u001b[1;32m   2368\u001b[0m \u001b[39m    \"\"\"\u001b[39;00m\n\u001b[0;32m-> 2369\u001b[0m     \u001b[39mreturn\u001b[39;00m \u001b[39mself\u001b[39;49m\u001b[39m.\u001b[39;49m_wrap_pool_connect(\n\u001b[1;32m   2370\u001b[0m         \u001b[39mself\u001b[39;49m\u001b[39m.\u001b[39;49mpool\u001b[39m.\u001b[39;49munique_connection, _connection\n\u001b[1;32m   2371\u001b[0m     )\n",
      "File \u001b[0;32m/opt/conda/lib/python3.8/site-packages/sqlalchemy/engine/base.py:2339\u001b[0m, in \u001b[0;36mEngine._wrap_pool_connect\u001b[0;34m(self, fn, connection)\u001b[0m\n\u001b[1;32m   2337\u001b[0m \u001b[39mexcept\u001b[39;00m dialect\u001b[39m.\u001b[39mdbapi\u001b[39m.\u001b[39mError \u001b[39mas\u001b[39;00m e:\n\u001b[1;32m   2338\u001b[0m     \u001b[39mif\u001b[39;00m connection \u001b[39mis\u001b[39;00m \u001b[39mNone\u001b[39;00m:\n\u001b[0;32m-> 2339\u001b[0m         Connection\u001b[39m.\u001b[39;49m_handle_dbapi_exception_noconnection(\n\u001b[1;32m   2340\u001b[0m             e, dialect, \u001b[39mself\u001b[39;49m\n\u001b[1;32m   2341\u001b[0m         )\n\u001b[1;32m   2342\u001b[0m     \u001b[39melse\u001b[39;00m:\n\u001b[1;32m   2343\u001b[0m         util\u001b[39m.\u001b[39mraise_(\n\u001b[1;32m   2344\u001b[0m             sys\u001b[39m.\u001b[39mexc_info()[\u001b[39m1\u001b[39m], with_traceback\u001b[39m=\u001b[39msys\u001b[39m.\u001b[39mexc_info()[\u001b[39m2\u001b[39m]\n\u001b[1;32m   2345\u001b[0m         )\n",
      "File \u001b[0;32m/opt/conda/lib/python3.8/site-packages/sqlalchemy/engine/base.py:1583\u001b[0m, in \u001b[0;36mConnection._handle_dbapi_exception_noconnection\u001b[0;34m(cls, e, dialect, engine)\u001b[0m\n\u001b[1;32m   1581\u001b[0m     util\u001b[39m.\u001b[39mraise_(newraise, with_traceback\u001b[39m=\u001b[39mexc_info[\u001b[39m2\u001b[39m], from_\u001b[39m=\u001b[39me)\n\u001b[1;32m   1582\u001b[0m \u001b[39melif\u001b[39;00m should_wrap:\n\u001b[0;32m-> 1583\u001b[0m     util\u001b[39m.\u001b[39;49mraise_(\n\u001b[1;32m   1584\u001b[0m         sqlalchemy_exception, with_traceback\u001b[39m=\u001b[39;49mexc_info[\u001b[39m2\u001b[39;49m], from_\u001b[39m=\u001b[39;49me\n\u001b[1;32m   1585\u001b[0m     )\n\u001b[1;32m   1586\u001b[0m \u001b[39melse\u001b[39;00m:\n\u001b[1;32m   1587\u001b[0m     util\u001b[39m.\u001b[39mraise_(exc_info[\u001b[39m1\u001b[39m], with_traceback\u001b[39m=\u001b[39mexc_info[\u001b[39m2\u001b[39m])\n",
      "File \u001b[0;32m/opt/conda/lib/python3.8/site-packages/sqlalchemy/util/compat.py:182\u001b[0m, in \u001b[0;36mraise_\u001b[0;34m(***failed resolving arguments***)\u001b[0m\n\u001b[1;32m    179\u001b[0m     exception\u001b[39m.\u001b[39m__cause__ \u001b[39m=\u001b[39m replace_context\n\u001b[1;32m    181\u001b[0m \u001b[39mtry\u001b[39;00m:\n\u001b[0;32m--> 182\u001b[0m     \u001b[39mraise\u001b[39;00m exception\n\u001b[1;32m    183\u001b[0m \u001b[39mfinally\u001b[39;00m:\n\u001b[1;32m    184\u001b[0m     \u001b[39m# credit to\u001b[39;00m\n\u001b[1;32m    185\u001b[0m     \u001b[39m# https://cosmicpercolator.com/2016/01/13/exception-leaks-in-python-2-and-3/\u001b[39;00m\n\u001b[1;32m    186\u001b[0m     \u001b[39m# as the __traceback__ object creates a cycle\u001b[39;00m\n\u001b[1;32m    187\u001b[0m     \u001b[39mdel\u001b[39;00m exception, replace_context, from_, with_traceback\n",
      "File \u001b[0;32m/opt/conda/lib/python3.8/site-packages/sqlalchemy/engine/base.py:2336\u001b[0m, in \u001b[0;36mEngine._wrap_pool_connect\u001b[0;34m(self, fn, connection)\u001b[0m\n\u001b[1;32m   2334\u001b[0m dialect \u001b[39m=\u001b[39m \u001b[39mself\u001b[39m\u001b[39m.\u001b[39mdialect\n\u001b[1;32m   2335\u001b[0m \u001b[39mtry\u001b[39;00m:\n\u001b[0;32m-> 2336\u001b[0m     \u001b[39mreturn\u001b[39;00m fn()\n\u001b[1;32m   2337\u001b[0m \u001b[39mexcept\u001b[39;00m dialect\u001b[39m.\u001b[39mdbapi\u001b[39m.\u001b[39mError \u001b[39mas\u001b[39;00m e:\n\u001b[1;32m   2338\u001b[0m     \u001b[39mif\u001b[39;00m connection \u001b[39mis\u001b[39;00m \u001b[39mNone\u001b[39;00m:\n",
      "File \u001b[0;32m/opt/conda/lib/python3.8/site-packages/sqlalchemy/pool/base.py:304\u001b[0m, in \u001b[0;36mPool.unique_connection\u001b[0;34m(self)\u001b[0m\n\u001b[1;32m    292\u001b[0m \u001b[39mdef\u001b[39;00m \u001b[39munique_connection\u001b[39m(\u001b[39mself\u001b[39m):\n\u001b[1;32m    293\u001b[0m     \u001b[39m\"\"\"Produce a DBAPI connection that is not referenced by any\u001b[39;00m\n\u001b[1;32m    294\u001b[0m \u001b[39m    thread-local context.\u001b[39;00m\n\u001b[1;32m    295\u001b[0m \n\u001b[0;32m   (...)\u001b[0m\n\u001b[1;32m    302\u001b[0m \n\u001b[1;32m    303\u001b[0m \u001b[39m    \"\"\"\u001b[39;00m\n\u001b[0;32m--> 304\u001b[0m     \u001b[39mreturn\u001b[39;00m _ConnectionFairy\u001b[39m.\u001b[39;49m_checkout(\u001b[39mself\u001b[39;49m)\n",
      "File \u001b[0;32m/opt/conda/lib/python3.8/site-packages/sqlalchemy/pool/base.py:778\u001b[0m, in \u001b[0;36m_ConnectionFairy._checkout\u001b[0;34m(cls, pool, threadconns, fairy)\u001b[0m\n\u001b[1;32m    775\u001b[0m \u001b[39m@classmethod\u001b[39m\n\u001b[1;32m    776\u001b[0m \u001b[39mdef\u001b[39;00m \u001b[39m_checkout\u001b[39m(\u001b[39mcls\u001b[39m, pool, threadconns\u001b[39m=\u001b[39m\u001b[39mNone\u001b[39;00m, fairy\u001b[39m=\u001b[39m\u001b[39mNone\u001b[39;00m):\n\u001b[1;32m    777\u001b[0m     \u001b[39mif\u001b[39;00m \u001b[39mnot\u001b[39;00m fairy:\n\u001b[0;32m--> 778\u001b[0m         fairy \u001b[39m=\u001b[39m _ConnectionRecord\u001b[39m.\u001b[39;49mcheckout(pool)\n\u001b[1;32m    780\u001b[0m         fairy\u001b[39m.\u001b[39m_pool \u001b[39m=\u001b[39m pool\n\u001b[1;32m    781\u001b[0m         fairy\u001b[39m.\u001b[39m_counter \u001b[39m=\u001b[39m \u001b[39m0\u001b[39m\n",
      "File \u001b[0;32m/opt/conda/lib/python3.8/site-packages/sqlalchemy/pool/base.py:495\u001b[0m, in \u001b[0;36m_ConnectionRecord.checkout\u001b[0;34m(cls, pool)\u001b[0m\n\u001b[1;32m    493\u001b[0m \u001b[39m@classmethod\u001b[39m\n\u001b[1;32m    494\u001b[0m \u001b[39mdef\u001b[39;00m \u001b[39mcheckout\u001b[39m(\u001b[39mcls\u001b[39m, pool):\n\u001b[0;32m--> 495\u001b[0m     rec \u001b[39m=\u001b[39m pool\u001b[39m.\u001b[39;49m_do_get()\n\u001b[1;32m    496\u001b[0m     \u001b[39mtry\u001b[39;00m:\n\u001b[1;32m    497\u001b[0m         dbapi_connection \u001b[39m=\u001b[39m rec\u001b[39m.\u001b[39mget_connection()\n",
      "File \u001b[0;32m/opt/conda/lib/python3.8/site-packages/sqlalchemy/pool/impl.py:140\u001b[0m, in \u001b[0;36mQueuePool._do_get\u001b[0;34m(self)\u001b[0m\n\u001b[1;32m    138\u001b[0m     \u001b[39mexcept\u001b[39;00m:\n\u001b[1;32m    139\u001b[0m         \u001b[39mwith\u001b[39;00m util\u001b[39m.\u001b[39msafe_reraise():\n\u001b[0;32m--> 140\u001b[0m             \u001b[39mself\u001b[39m\u001b[39m.\u001b[39m_dec_overflow()\n\u001b[1;32m    141\u001b[0m \u001b[39melse\u001b[39;00m:\n\u001b[1;32m    142\u001b[0m     \u001b[39mreturn\u001b[39;00m \u001b[39mself\u001b[39m\u001b[39m.\u001b[39m_do_get()\n",
      "File \u001b[0;32m/opt/conda/lib/python3.8/site-packages/sqlalchemy/util/langhelpers.py:68\u001b[0m, in \u001b[0;36msafe_reraise.__exit__\u001b[0;34m(self, type_, value, traceback)\u001b[0m\n\u001b[1;32m     66\u001b[0m     \u001b[39mself\u001b[39m\u001b[39m.\u001b[39m_exc_info \u001b[39m=\u001b[39m \u001b[39mNone\u001b[39;00m  \u001b[39m# remove potential circular references\u001b[39;00m\n\u001b[1;32m     67\u001b[0m     \u001b[39mif\u001b[39;00m \u001b[39mnot\u001b[39;00m \u001b[39mself\u001b[39m\u001b[39m.\u001b[39mwarn_only:\n\u001b[0;32m---> 68\u001b[0m         compat\u001b[39m.\u001b[39;49mraise_(\n\u001b[1;32m     69\u001b[0m             exc_value,\n\u001b[1;32m     70\u001b[0m             with_traceback\u001b[39m=\u001b[39;49mexc_tb,\n\u001b[1;32m     71\u001b[0m         )\n\u001b[1;32m     72\u001b[0m \u001b[39melse\u001b[39;00m:\n\u001b[1;32m     73\u001b[0m     \u001b[39mif\u001b[39;00m \u001b[39mnot\u001b[39;00m compat\u001b[39m.\u001b[39mpy3k \u001b[39mand\u001b[39;00m \u001b[39mself\u001b[39m\u001b[39m.\u001b[39m_exc_info \u001b[39mand\u001b[39;00m \u001b[39mself\u001b[39m\u001b[39m.\u001b[39m_exc_info[\u001b[39m1\u001b[39m]:\n\u001b[1;32m     74\u001b[0m         \u001b[39m# emulate Py3K's behavior of telling us when an exception\u001b[39;00m\n\u001b[1;32m     75\u001b[0m         \u001b[39m# occurs in an exception handler.\u001b[39;00m\n",
      "File \u001b[0;32m/opt/conda/lib/python3.8/site-packages/sqlalchemy/util/compat.py:182\u001b[0m, in \u001b[0;36mraise_\u001b[0;34m(***failed resolving arguments***)\u001b[0m\n\u001b[1;32m    179\u001b[0m     exception\u001b[39m.\u001b[39m__cause__ \u001b[39m=\u001b[39m replace_context\n\u001b[1;32m    181\u001b[0m \u001b[39mtry\u001b[39;00m:\n\u001b[0;32m--> 182\u001b[0m     \u001b[39mraise\u001b[39;00m exception\n\u001b[1;32m    183\u001b[0m \u001b[39mfinally\u001b[39;00m:\n\u001b[1;32m    184\u001b[0m     \u001b[39m# credit to\u001b[39;00m\n\u001b[1;32m    185\u001b[0m     \u001b[39m# https://cosmicpercolator.com/2016/01/13/exception-leaks-in-python-2-and-3/\u001b[39;00m\n\u001b[1;32m    186\u001b[0m     \u001b[39m# as the __traceback__ object creates a cycle\u001b[39;00m\n\u001b[1;32m    187\u001b[0m     \u001b[39mdel\u001b[39;00m exception, replace_context, from_, with_traceback\n",
      "File \u001b[0;32m/opt/conda/lib/python3.8/site-packages/sqlalchemy/pool/impl.py:137\u001b[0m, in \u001b[0;36mQueuePool._do_get\u001b[0;34m(self)\u001b[0m\n\u001b[1;32m    135\u001b[0m \u001b[39mif\u001b[39;00m \u001b[39mself\u001b[39m\u001b[39m.\u001b[39m_inc_overflow():\n\u001b[1;32m    136\u001b[0m     \u001b[39mtry\u001b[39;00m:\n\u001b[0;32m--> 137\u001b[0m         \u001b[39mreturn\u001b[39;00m \u001b[39mself\u001b[39;49m\u001b[39m.\u001b[39;49m_create_connection()\n\u001b[1;32m    138\u001b[0m     \u001b[39mexcept\u001b[39;00m:\n\u001b[1;32m    139\u001b[0m         \u001b[39mwith\u001b[39;00m util\u001b[39m.\u001b[39msafe_reraise():\n",
      "File \u001b[0;32m/opt/conda/lib/python3.8/site-packages/sqlalchemy/pool/base.py:309\u001b[0m, in \u001b[0;36mPool._create_connection\u001b[0;34m(self)\u001b[0m\n\u001b[1;32m    306\u001b[0m \u001b[39mdef\u001b[39;00m \u001b[39m_create_connection\u001b[39m(\u001b[39mself\u001b[39m):\n\u001b[1;32m    307\u001b[0m     \u001b[39m\"\"\"Called by subclasses to create a new ConnectionRecord.\"\"\"\u001b[39;00m\n\u001b[0;32m--> 309\u001b[0m     \u001b[39mreturn\u001b[39;00m _ConnectionRecord(\u001b[39mself\u001b[39;49m)\n",
      "File \u001b[0;32m/opt/conda/lib/python3.8/site-packages/sqlalchemy/pool/base.py:440\u001b[0m, in \u001b[0;36m_ConnectionRecord.__init__\u001b[0;34m(self, pool, connect)\u001b[0m\n\u001b[1;32m    438\u001b[0m \u001b[39mself\u001b[39m\u001b[39m.\u001b[39m__pool \u001b[39m=\u001b[39m pool\n\u001b[1;32m    439\u001b[0m \u001b[39mif\u001b[39;00m connect:\n\u001b[0;32m--> 440\u001b[0m     \u001b[39mself\u001b[39;49m\u001b[39m.\u001b[39;49m__connect(first_connect_check\u001b[39m=\u001b[39;49m\u001b[39mTrue\u001b[39;49;00m)\n\u001b[1;32m    441\u001b[0m \u001b[39mself\u001b[39m\u001b[39m.\u001b[39mfinalize_callback \u001b[39m=\u001b[39m deque()\n",
      "File \u001b[0;32m/opt/conda/lib/python3.8/site-packages/sqlalchemy/pool/base.py:661\u001b[0m, in \u001b[0;36m_ConnectionRecord.__connect\u001b[0;34m(self, first_connect_check)\u001b[0m\n\u001b[1;32m    659\u001b[0m \u001b[39mexcept\u001b[39;00m \u001b[39mException\u001b[39;00m \u001b[39mas\u001b[39;00m e:\n\u001b[1;32m    660\u001b[0m     \u001b[39mwith\u001b[39;00m util\u001b[39m.\u001b[39msafe_reraise():\n\u001b[0;32m--> 661\u001b[0m         pool\u001b[39m.\u001b[39mlogger\u001b[39m.\u001b[39mdebug(\u001b[39m\"\u001b[39m\u001b[39mError on connect(): \u001b[39m\u001b[39m%s\u001b[39;00m\u001b[39m\"\u001b[39m, e)\n\u001b[1;32m    662\u001b[0m \u001b[39melse\u001b[39;00m:\n\u001b[1;32m    663\u001b[0m     \u001b[39mif\u001b[39;00m first_connect_check:\n",
      "File \u001b[0;32m/opt/conda/lib/python3.8/site-packages/sqlalchemy/util/langhelpers.py:68\u001b[0m, in \u001b[0;36msafe_reraise.__exit__\u001b[0;34m(self, type_, value, traceback)\u001b[0m\n\u001b[1;32m     66\u001b[0m     \u001b[39mself\u001b[39m\u001b[39m.\u001b[39m_exc_info \u001b[39m=\u001b[39m \u001b[39mNone\u001b[39;00m  \u001b[39m# remove potential circular references\u001b[39;00m\n\u001b[1;32m     67\u001b[0m     \u001b[39mif\u001b[39;00m \u001b[39mnot\u001b[39;00m \u001b[39mself\u001b[39m\u001b[39m.\u001b[39mwarn_only:\n\u001b[0;32m---> 68\u001b[0m         compat\u001b[39m.\u001b[39;49mraise_(\n\u001b[1;32m     69\u001b[0m             exc_value,\n\u001b[1;32m     70\u001b[0m             with_traceback\u001b[39m=\u001b[39;49mexc_tb,\n\u001b[1;32m     71\u001b[0m         )\n\u001b[1;32m     72\u001b[0m \u001b[39melse\u001b[39;00m:\n\u001b[1;32m     73\u001b[0m     \u001b[39mif\u001b[39;00m \u001b[39mnot\u001b[39;00m compat\u001b[39m.\u001b[39mpy3k \u001b[39mand\u001b[39;00m \u001b[39mself\u001b[39m\u001b[39m.\u001b[39m_exc_info \u001b[39mand\u001b[39;00m \u001b[39mself\u001b[39m\u001b[39m.\u001b[39m_exc_info[\u001b[39m1\u001b[39m]:\n\u001b[1;32m     74\u001b[0m         \u001b[39m# emulate Py3K's behavior of telling us when an exception\u001b[39;00m\n\u001b[1;32m     75\u001b[0m         \u001b[39m# occurs in an exception handler.\u001b[39;00m\n",
      "File \u001b[0;32m/opt/conda/lib/python3.8/site-packages/sqlalchemy/util/compat.py:182\u001b[0m, in \u001b[0;36mraise_\u001b[0;34m(***failed resolving arguments***)\u001b[0m\n\u001b[1;32m    179\u001b[0m     exception\u001b[39m.\u001b[39m__cause__ \u001b[39m=\u001b[39m replace_context\n\u001b[1;32m    181\u001b[0m \u001b[39mtry\u001b[39;00m:\n\u001b[0;32m--> 182\u001b[0m     \u001b[39mraise\u001b[39;00m exception\n\u001b[1;32m    183\u001b[0m \u001b[39mfinally\u001b[39;00m:\n\u001b[1;32m    184\u001b[0m     \u001b[39m# credit to\u001b[39;00m\n\u001b[1;32m    185\u001b[0m     \u001b[39m# https://cosmicpercolator.com/2016/01/13/exception-leaks-in-python-2-and-3/\u001b[39;00m\n\u001b[1;32m    186\u001b[0m     \u001b[39m# as the __traceback__ object creates a cycle\u001b[39;00m\n\u001b[1;32m    187\u001b[0m     \u001b[39mdel\u001b[39;00m exception, replace_context, from_, with_traceback\n",
      "File \u001b[0;32m/opt/conda/lib/python3.8/site-packages/sqlalchemy/pool/base.py:656\u001b[0m, in \u001b[0;36m_ConnectionRecord.__connect\u001b[0;34m(self, first_connect_check)\u001b[0m\n\u001b[1;32m    654\u001b[0m \u001b[39mtry\u001b[39;00m:\n\u001b[1;32m    655\u001b[0m     \u001b[39mself\u001b[39m\u001b[39m.\u001b[39mstarttime \u001b[39m=\u001b[39m time\u001b[39m.\u001b[39mtime()\n\u001b[0;32m--> 656\u001b[0m     connection \u001b[39m=\u001b[39m pool\u001b[39m.\u001b[39;49m_invoke_creator(\u001b[39mself\u001b[39;49m)\n\u001b[1;32m    657\u001b[0m     pool\u001b[39m.\u001b[39mlogger\u001b[39m.\u001b[39mdebug(\u001b[39m\"\u001b[39m\u001b[39mCreated new connection \u001b[39m\u001b[39m%r\u001b[39;00m\u001b[39m\"\u001b[39m, connection)\n\u001b[1;32m    658\u001b[0m     \u001b[39mself\u001b[39m\u001b[39m.\u001b[39mconnection \u001b[39m=\u001b[39m connection\n",
      "File \u001b[0;32m/opt/conda/lib/python3.8/site-packages/sqlalchemy/engine/strategies.py:114\u001b[0m, in \u001b[0;36mDefaultEngineStrategy.create.<locals>.connect\u001b[0;34m(connection_record)\u001b[0m\n\u001b[1;32m    112\u001b[0m         \u001b[39mif\u001b[39;00m connection \u001b[39mis\u001b[39;00m \u001b[39mnot\u001b[39;00m \u001b[39mNone\u001b[39;00m:\n\u001b[1;32m    113\u001b[0m             \u001b[39mreturn\u001b[39;00m connection\n\u001b[0;32m--> 114\u001b[0m \u001b[39mreturn\u001b[39;00m dialect\u001b[39m.\u001b[39;49mconnect(\u001b[39m*\u001b[39;49mcargs, \u001b[39m*\u001b[39;49m\u001b[39m*\u001b[39;49mcparams)\n",
      "File \u001b[0;32m/opt/conda/lib/python3.8/site-packages/sqlalchemy/engine/default.py:508\u001b[0m, in \u001b[0;36mDefaultDialect.connect\u001b[0;34m(self, *cargs, **cparams)\u001b[0m\n\u001b[1;32m    506\u001b[0m \u001b[39mdef\u001b[39;00m \u001b[39mconnect\u001b[39m(\u001b[39mself\u001b[39m, \u001b[39m*\u001b[39mcargs, \u001b[39m*\u001b[39m\u001b[39m*\u001b[39mcparams):\n\u001b[1;32m    507\u001b[0m     \u001b[39m# inherits the docstring from interfaces.Dialect.connect\u001b[39;00m\n\u001b[0;32m--> 508\u001b[0m     \u001b[39mreturn\u001b[39;00m \u001b[39mself\u001b[39;49m\u001b[39m.\u001b[39;49mdbapi\u001b[39m.\u001b[39;49mconnect(\u001b[39m*\u001b[39;49mcargs, \u001b[39m*\u001b[39;49m\u001b[39m*\u001b[39;49mcparams)\n",
      "File \u001b[0;32m/opt/conda/lib/python3.8/site-packages/pymysql/connections.py:353\u001b[0m, in \u001b[0;36mConnection.__init__\u001b[0;34m(self, user, password, host, database, unix_socket, port, charset, sql_mode, read_default_file, conv, use_unicode, client_flag, cursorclass, init_command, connect_timeout, read_default_group, autocommit, local_infile, max_allowed_packet, defer_connect, auth_plugin_map, read_timeout, write_timeout, bind_address, binary_prefix, program_name, server_public_key, ssl, ssl_ca, ssl_cert, ssl_disabled, ssl_key, ssl_verify_cert, ssl_verify_identity, compress, named_pipe, passwd, db)\u001b[0m\n\u001b[1;32m    351\u001b[0m     \u001b[39mself\u001b[39m\u001b[39m.\u001b[39m_sock \u001b[39m=\u001b[39m \u001b[39mNone\u001b[39;00m\n\u001b[1;32m    352\u001b[0m \u001b[39melse\u001b[39;00m:\n\u001b[0;32m--> 353\u001b[0m     \u001b[39mself\u001b[39;49m\u001b[39m.\u001b[39;49mconnect()\n",
      "File \u001b[0;32m/opt/conda/lib/python3.8/site-packages/pymysql/connections.py:664\u001b[0m, in \u001b[0;36mConnection.connect\u001b[0;34m(self, sock)\u001b[0m\n\u001b[1;32m    662\u001b[0m     \u001b[39mif\u001b[39;00m DEBUG:\n\u001b[1;32m    663\u001b[0m         \u001b[39mprint\u001b[39m(exc\u001b[39m.\u001b[39mtraceback)\n\u001b[0;32m--> 664\u001b[0m     \u001b[39mraise\u001b[39;00m exc\n\u001b[1;32m    666\u001b[0m \u001b[39m# If e is neither DatabaseError or IOError, It's a bug.\u001b[39;00m\n\u001b[1;32m    667\u001b[0m \u001b[39m# But raising AssertionError hides original error.\u001b[39;00m\n\u001b[1;32m    668\u001b[0m \u001b[39m# So just reraise it.\u001b[39;00m\n\u001b[1;32m    669\u001b[0m \u001b[39mraise\u001b[39;00m\n",
      "\u001b[0;31mOperationalError\u001b[0m: (pymysql.err.OperationalError) (2003, \"Can't connect to MySQL server on 'None' ([Errno -2] Name or service not known)\")\n(Background on this error at: http://sqlalche.me/e/13/e3q8)"
     ]
    }
   ],
   "source": [
    "#| export\n",
    "\n",
    "load_dotenv()\n",
    "\n",
    "USER = os.getenv('USER')\n",
    "PASS = os.getenv('PASS')\n",
    "HOST = os.getenv('IP')\n",
    "PORT = os.getenv('PORT')\n",
    "DB = os.getenv('DB')\n",
    "\n",
    "sqlEngine = create_engine(\n",
    "    f'mysql+pymysql://{USER}:{PASS}@{HOST}/{DB}', pool_recycle=3600\n",
    ")\n",
    "dbConnection = sqlEngine.connect()\n",
    "\n",
    "\n",
    "new_version ='01'\n",
    "\n",
    "for table in tables.national_list:\n",
    "    df = pd.read_sql(f\"select * from {table.table_name}\", dbConnection)\n",
    "    df.to_csv(table.version(new_version),index=False)\n",
    "    print(df.info)  \n",
    "dbConnection.close()"
   ]
  },
  {
   "cell_type": "code",
   "execution_count": null,
   "metadata": {},
   "outputs": [],
   "source": []
  }
 ],
 "metadata": {
  "kernelspec": {
   "display_name": "Python 3.10.6 ('base')",
   "language": "python",
   "name": "python3"
  },
  "language_info": {
   "name": "python",
   "version": "3.8.6"
  },
  "vscode": {
   "interpreter": {
    "hash": "d4d1e4263499bec80672ea0156c357c1ee493ec2b1c70f0acce89fc37c4a6abe"
   }
  }
 },
 "nbformat": 4,
 "nbformat_minor": 2
}
